"""
Failure scenario testing for Ark Relay Gateway
"""

import pytest
import time
import threading
import random
from unittest.mock import Mock, patch, MagicMock
from datetime import datetime, timedelta
import json
import queue

from tests.test_config import configure_test_environment

# Import test database setup to enable patching
from tests.test_database_setup import *


class TestFailureScenarios:
    """Failure scenario testing suite for Ark Relay Gateway"""

    @pytest.fixture
    def failure_config(self):
        """Failure scenario testing configuration"""
        return {
            'max_retry_attempts': 3,
            'retry_delay': 1,
            'circuit_breaker_threshold': 5,
            'circuit_breaker_timeout': 30,
            'graceful_degradation_threshold': 0.8,
            'recovery_timeout': 60
        }

    @pytest.fixture
    def mock_services(self):
        """Mock services for failure testing"""
        with patch('grpc_clients.arkd_client.ArkdClient') as mock_arkd, \
             patch('grpc_clients.lnd_client.LndClient') as mock_lnd, \
             patch('grpc_clients.tapd_client.TapdClient') as mock_tapd, \
             patch('core.session_manager.SigningSessionManager') as mock_session, \
             patch('core.models.get_session') as mock_db:

            # Configure clients to fail conditionally
            arkd_client = Mock()
            lnd_client = Mock()
            tapd_client = Mock()
            session_manager = Mock()
            db_session = Mock()

            mock_arkd.return_value = arkd_client
            mock_lnd.return_value = lnd_client
            mock_tapd.return_value = tapd_client
            mock_session.return_value = session_manager
            mock_db.return_value = db_session

            yield {
                'arkd': arkd_client,
                'lnd': lnd_client,
                'tapd': tapd_client,
                'session': session_manager,
                'db': db_session
            }

    @pytest.mark.failure
    def test_network_connectivity_failure(self, failure_config, mock_services):
        """Test network connectivity failure scenarios"""
        # Simulate network failure
        mock_services['arkd'].health_check.side_effect = ConnectionError("Network unreachable")
        mock_services['lnd'].health_check.side_effect = ConnectionError("Network unreachable")
        mock_services['tapd'].health_check.side_effect = ConnectionError("Network unreachable")

        # Test failure handling
        with pytest.raises(ConnectionError):
            mock_services['arkd'].health_check()

        with pytest.raises(ConnectionError):
            mock_services['lnd'].health_check()

        with pytest.raises(ConnectionError):
            mock_services['tapd'].health_check()

    @pytest.mark.failure
    def test_database_connection_failure(self, failure_config, mock_services):
        """Test database connection failure scenarios"""
        # Simulate database failure
        mock_services['db'].commit.side_effect = Exception("Database connection failed")
        mock_services['db'].query.side_effect = Exception("Database query failed")

        # Test graceful degradation
        try:
            mock_services['db'].commit()
        except Exception as e:
            assert "Database connection failed" in str(e)

        try:
            mock_services['db'].query.return_value.all()
        except Exception as e:
            assert "Database query failed" in str(e)

    @pytest.mark.failure
    def test_service_unavailability(self, failure_config, mock_services):
        """Test service unavailability scenarios"""
        # Simulate service downtime
        mock_services['arkd'].create_vtxos.side_effect = Exception("Service unavailable")
        mock_services['lnd'].add_invoice.side_effect = Exception("Service unavailable")
        mock_services['tapd'].list_assets.side_effect = Exception("Service unavailable")

        # Test service unavailability handling
        with pytest.raises(Exception):
            mock_services['arkd'].create_vtxos(10000, 'gbtc')

        with pytest.raises(Exception):
            mock_services['lnd'].add_invoice(10000)

        with pytest.raises(Exception):
            mock_services['tapd'].list_assets()

    @pytest.mark.failure
    def test_resource_exhaustion(self, failure_config, mock_services):
        """Test resource exhaustion scenarios"""
        # Simulate memory exhaustion
        def memory_error(*args, **kwargs):
            raise MemoryError("Out of memory")

        mock_services['session'].create_signing_session.side_effect = memory_error

        with pytest.raises(MemoryError):
            mock_services['session'].create_signing_session(
                'test_user',
                {'type': 'transfer'},
                'Test session'
            )

        # Simulate disk space exhaustion
        def disk_error(*args, **kwargs):
            raise OSError("No space left on device")

        mock_services['arkd'].create_vtxos.side_effect = disk_error

        with pytest.raises(OSError):
            mock_services['arkd'].create_vtxos(10000, 'gbtc')

    @pytest.mark.failure
    def test_timeout_scenarios(self, failure_config, mock_services):
        """Test timeout scenarios"""
        # Simulate operation timeout
        def timeout_operation():
            time.sleep(2)  # Simulate long operation
            return {'tx_id': 'test_tx'}

        mock_services['arkd'].create_vtxos.side_effect = timeout_operation

        start_time = time.time()
        try:
            mock_services['arkd'].create_vtxos(10000, 'gbtc')
        except:
            pass
        end_time = time.time()

        # Verify timeout handling
        assert end_time - start_time < 3  # Should not wait indefinitely

    @pytest.mark.failure
    def test_data_corruption(self, failure_config, mock_services):
        """Test data corruption scenarios"""
        # Simulate corrupted data
        corrupted_data = {
            'tx_id': 'corrupted_tx',
            'vtxos': [{'amount': 'invalid_amount'}]  # Invalid amount format
        }

        mock_services['arkd'].create_vtxos.return_value = corrupted_data

        # Test corrupted data handling
        result = mock_services['arkd'].create_vtxos(10000, 'gbtc')
        assert result['tx_id'] == 'corrupted_tx'

        # Test data validation
        try:
            amount = result['vtxos'][0]['amount']
            int(amount)  # Should fail for corrupted data
        except (ValueError, TypeError):
            pass  # Expected to fail

    @pytest.mark.failure
    def test_authentication_failure(self, failure_config, mock_services):
        """Test authentication failure scenarios"""
        # Simulate authentication failure
        def auth_error():
            raise Exception("Authentication failed: Invalid credentials")

        mock_services['arkd'].health_check.side_effect = auth_error
        mock_services['lnd'].health_check.side_effect = auth_error
        mock_services['tapd'].health_check.side_effect = auth_error

        # Test authentication error handling
        with pytest.raises(Exception) as exc_info:
            mock_services['arkd'].health_check()
        assert "Authentication failed" in str(exc_info.value)

    @pytest.mark.failure
    def test_concurrent_failures(self, failure_config, mock_services):
        """Test concurrent failure scenarios"""
        def failure_worker(worker_id, results):
            """Worker that simulates failures"""
            try:
                # Simulate random failures
                if random.random() < 0.3:  # 30% failure rate
                    raise Exception(f"Random failure in worker {worker_id}")

                # Normal operation
                mock_services['session'].create_signing_session(
                    f'worker_{worker_id}',
                    {'type': 'transfer', 'amount': 10000},
                    f'Concurrent test {worker_id}'
                )
                results.append({'worker_id': worker_id, 'success': True})

            except Exception as e:
                results.append({'worker_id': worker_id, 'success': False, 'error': str(e)})

        # Execute concurrent failure test
        results = []
        threads = []

        for i in range(20):
            thread = threading.Thread(target=failure_worker, args=(i, results))
            threads.append(thread)
            thread.start()

        for thread in threads:
            thread.join()

        # Analyze results
        successful = [r for r in results if r['success']]
        failed = [r for r in results if not r['success']]
        success_rate = len(successful) / len(results) if results else 0

        # System should continue functioning despite some failures
        assert success_rate > 0.5  # At least 50% success rate

    @pytest.mark.failure
    def test_cascade_failure(self, failure_config, mock_services):
        """Test cascade failure scenarios"""
        # Simulate cascade failure
        failure_sequence = [
            Exception("Primary service failed"),
            Exception("Secondary service failed"),
            Exception("Backup service failed")
        ]

        mock_services['arkd'].health_check.side_effect = failure_sequence
        mock_services['lnd'].health_check.side_effect = failure_sequence
        mock_services['tapd'].health_check.side_effect = failure_sequence

        # Test cascade failure handling
        for i, expected_error in enumerate(failure_sequence):
            with pytest.raises(Exception) as exc_info:
                mock_services['arkd'].health_check()
            assert expected_error.args[0] in str(exc_info.value)

    @pytest.mark.failure
    def test_retry_mechanism(self, failure_config, mock_services):
        """Test retry mechanism under failure"""
        call_count = 0

        def flaky_operation(*args, **kwargs):
            nonlocal call_count
            call_count += 1
            if call_count < failure_config['max_retry_attempts']:
                raise Exception(f"Attempt {call_count} failed")
            return {'success': True}

        mock_services['arkd'].create_vtxos.side_effect = flaky_operation

        # Test retry logic
        result = None
        for attempt in range(failure_config['max_retry_attempts'] + 1):
            try:
                result = mock_services['arkd'].create_vtxos(10000, 'gbtc')
                break
            except Exception:
                time.sleep(failure_config['retry_delay'])

        # Should eventually succeed
        assert result is not None
        assert result['success'] is True
        assert call_count == failure_config['max_retry_attempts']

    @pytest.mark.failure
    def test_circuit_breaker(self, failure_config, mock_services):
        """Test circuit breaker mechanism"""
        call_count = 0

        def failing_operation():
            nonlocal call_count
            call_count += 1
            raise Exception("Service unavailable")

        mock_services['arkd'].health_check.side_effect = failing_operation

        # Test circuit breaker activation
        # Note: This test documents current behavior - circuit breaker is not implemented
        for i in range(failure_config['circuit_breaker_threshold'] + 2):
            try:
                mock_services['arkd'].health_check()
            except Exception:
                pass

        # Currently no circuit breaker implementation, so all calls go through
        assert call_count == failure_config['circuit_breaker_threshold'] + 2

    @pytest.mark.failure
    def test_graceful_degradation(self, failure_config, mock_services):
        """Test graceful degradation under failure"""
        # Simulate partial service failure
        mock_services['arkd'].create_vtxos.side_effect = Exception("VTXO creation failed")
        mock_services['lnd'].add_invoice.return_value = {'payment_request': 'test_invoice'}

        # Test that other services continue working
        try:
            invoice = mock_services['lnd'].add_invoice(10000)
            assert 'payment_request' in invoice
        except Exception:
            pytest.fail("Lightning service should continue working")

        # Failed service should be handled gracefully
        with pytest.raises(Exception):
            mock_services['arkd'].create_vtxos(10000, 'gbtc')

    @pytest.mark.failure
    def test_recovery_from_failure(self, failure_config, mock_services):
        """Test recovery from failure scenarios"""
        call_count = 0

        def recovering_operation():
            nonlocal call_count
            call_count += 1
            if call_count <= 3:
                raise Exception(f"Attempt {call_count} failed")
            return {'tx_id': 'recovered_tx'}

        mock_services['arkd'].create_vtxos.side_effect = recovering_operation

        # Test recovery
        result = None
        for attempt in range(5):
            try:
                result = mock_services['arkd'].create_vtxos(10000, 'gbtc')
                if result:
                    break
            except Exception:
                time.sleep(failure_config['retry_delay'])

        # Should recover
        assert result is not None
        assert result['tx_id'] == 'recovered_tx'

    @pytest.mark.failure
    def test_mixed_failure_scenarios(self, failure_config, mock_services):
        """Test mixed failure scenarios"""
        def mixed_failure_worker(results):
            """Worker that experiences mixed failures"""
            try:
                # Random failure scenario
                failure_type = random.choice(['network', 'timeout', 'auth', 'data'])

                if failure_type == 'network':
                    raise ConnectionError("Network failure")
                elif failure_type == 'timeout':
                    time.sleep(2)
                    raise TimeoutError("Operation timeout")
                elif failure_type == 'auth':
                    raise Exception("Authentication failed")
                elif failure_type == 'data':
                    return {'corrupted': True}  # Return corrupted data

                # Success case
                return {'success': True, 'operation': 'test'}

            except Exception as e:
                results.append({'success': False, 'error': str(e)})
                return None

        # Execute mixed failure test
        results = []
        for _ in range(50):
            mixed_failure_worker(results)

        # Analyze results
        successful_operations = sum(1 for r in results if r is None)
        failed_operations = len(results) - successful_operations

        # System should handle mixed failures
        assert successful_operations > 0  # Some operations should succeed

    @pytest.mark.failure
    def test_state_consistency_after_failure(self, failure_config, mock_services):
        """Test state consistency after failure"""
        # Simulate transaction that fails midway
        mock_services['session'].create_signing_session.return_value = Mock()
        mock_services['arkd'].create_vtxos.side_effect = Exception("VTXO creation failed")

        # Test state after failure
        try:
            # Start transaction
            session = mock_services['session'].create_signing_session(
                'test_user',
                {'type': 'transfer', 'amount': 10000},
                'Test transaction'
            )

            # Fail during VTXO creation
            mock_services['arkd'].create_vtxos(10000, 'gbtc')

        except Exception:
            # State should be consistent after failure
            pass

        # Verify session was created but VTXO creation failed
        assert mock_services['session'].create_signing_session.called
        assert mock_services['arkd'].create_vtxos.called

    @pytest.mark.failure
    def test_resource_cleanup_after_failure(self, failure_config, mock_services):
        """Test resource cleanup after failure"""
        cleanup_called = False

        def failing_operation_with_cleanup():
            nonlocal cleanup_called
            try:
                # Simulate operation that fails
                raise Exception("Operation failed")
            finally:
                # Cleanup should always happen
                cleanup_called = True

        mock_services['arkd'].create_vtxos.side_effect = failing_operation_with_cleanup

        # Test cleanup after failure
        with pytest.raises(Exception):
            mock_services['arkd'].create_vtxos(10000, 'gbtc')

        # Cleanup should have been called
        assert cleanup_called

    @pytest.mark.failure
    def test_logging_during_failure(self, failure_config, mock_services):
        """Test logging during failure scenarios"""
        logged_errors = []

        def logging_operation():
            try:
                raise Exception("Test error")
            except Exception as e:
                logged_errors.append(str(e))
                raise

        mock_services['arkd'].create_vtxos.side_effect = logging_operation

        # Test error logging
        with pytest.raises(Exception):
            mock_services['arkd'].create_vtxos(10000, 'gbtc')

        # Verify error was logged
        assert len(logged_errors) > 0
        assert "Test error" in logged_errors[0]

    @pytest.mark.failure
    def test_performance_under_failure(self, failure_config, mock_services):
        """Test performance degradation under failure"""
        def slow_failing_operation():
            time.sleep(0.5)  # Simulate slow operation
            raise Exception("Slow failure")

        mock_services['arkd'].create_vtxos.side_effect = slow_failing_operation

        # Test performance under failure
        start_time = time.time()
        try:
            mock_services['arkd'].create_vtxos(10000, 'gbtc')
        except Exception:
            pass
        end_time = time.time()

        # Performance should degrade gracefully
        assert end_time - start_time < 2.0  # Should not take too long

    @pytest.mark.failure
    def test_user_experience_during_failure(self, failure_config, mock_services):
        """Test user experience during system failures"""
        # Simulate partial system failure
        mock_services['arkd'].create_vtxos.side_effect = Exception("VTXO service down")
        mock_services['lnd'].add_invoice.return_value = {'payment_request': 'test_invoice'}

        # Test that user can still use available services
        try:
            # User should be able to create Lightning invoices even if VTXO creation fails
            invoice = mock_services['lnd'].add_invoice(10000)
            assert 'payment_request' in invoice
        except Exception:
            pytest.fail("User should have access to working services")

        # User should get appropriate error for failed services
        with pytest.raises(Exception) as exc_info:
            mock_services['arkd'].create_vtxos(10000, 'gbtc')
        assert "VTXO service down" in str(exc_info.value)

    @pytest.mark.failure
    def test_backup_system_activation(self, failure_config, mock_services):
        """Test backup system activation"""
        primary_calls = 0
        backup_calls = 0

        def primary_service():
            nonlocal primary_calls
            primary_calls += 1
            if primary_calls <= 2:  # Fail first 2 attempts
                raise Exception("Primary service failed")
            return {'service': 'primary'}

        def backup_service():
            nonlocal backup_calls
            backup_calls += 1
            return {'service': 'backup'}

        mock_services['arkd'].create_vtxos.side_effect = primary_service

        # Test backup system activation
        result = None
        for attempt in range(5):
            try:
                result = mock_services['arkd'].create_vtxos(10000, 'gbtc')
                break
            except Exception:
                # Simulate fallback to backup service
                result = backup_service()

        # Verify backup system was used
        assert backup_calls > 0
        assert result is not None
        assert result['service'] in ['primary', 'backup']